<mujoco model="schunk_hand">
    <compiler angle="radian" meshdir="environment_parts/" />

    <asset>
        <material name="metal" specular="1" shininess="0.1" reflectance="0.5" rgba="0.6 0.6 0.6 1"/>
        <material name="black2" rgba="0.149 0.149 0.149 1"/>
        <material name="wood2" rgba="0.56 0.37 0.29 1"/>
        <material name="gray2" rgba="0.4 0.4 0.4 1"/>
        <mesh name="SDH_Gehaeuse" file="schunk_hand/assets_schunk_hand/SDH_Gehaeuse.STL" scale="0.001 0.001 0.001"/>
        <mesh name="SDH_Gelenk_Finger1" file="schunk_hand/assets_schunk_hand/SDH_Gelenk_Finger1.STL" scale="0.001 0.001 0.001"/>
        <mesh name="SDH_Kuppe_Finger1" file="schunk_hand/assets_schunk_hand/SDH_Kuppe_Finger1.STL" scale="0.001 0.001 0.001"/>
        <mesh name="SDH_Mittelteil_Finger1" file="schunk_hand/assets_schunk_hand/SDH_Mittelteil_Finger1.STL" scale="0.001 0.001 0.001"/>
        <mesh name="Adapter" file="schunk_hand/assets_schunk_hand/Adapter.STL" scale="0.001 0.001 0.001"/>
    </asset>

    <actuator>
        <position name="finger_base_1" joint="finger_base_1" ctrllimited="true" ctrlrange="-2.9670597283903604 2.9670597283903604" kp="1" />
        <position name="finger_mittel_1" joint="finger_mittel_1" ctrllimited="true" ctrlrange="-2.9670597283903604 2.9670597283903604" kp="7" />
        <position name="finger_kuppe_1" joint="finger_kuppe_1" ctrllimited="true" ctrlrange="-2.9670597283903604 2.9670597283903604" kp="7" />
    </actuator>

    <worldbody>
        <light pos="0 0 1.5" dir="0 0 -1" directional="true"/>
        <!--geom name="ground" type="plane" size="0 0 1" pos="0 0 0" quat="1 0 0 0"  contype="0" group="0" /-->
        <body name="base_mount" pos="0 0 0.0" >
            <inertial pos="0.0 0.0 0.0" quat="1 0 0 0" mass="0.25" diaginertia="0.01 0.01 0.01"/>
            <geom type="mesh" mesh="Adapter" material="metal" group="1"/>
            <body name="Adapter" pos="0 0 0.09" >
                <geom type="mesh" mesh="SDH_Gehaeuse" material="metal" group="1"/>

                <body name="finger_mount1" pos="-0.035 0 0.025" axisangle="0 0 1 3.141592653589">
                    <joint name="finger_base_1" pos="0 0 0" axis="0 0 1" limited="true" range="-2.9670597283903604 2.9670597283903604" damping="0.1" stiffness="1.0"/>
                    <geom type="mesh" mesh="SDH_Gelenk_Finger1" material="metal" group="1" euler="1.57079632679 1.57079632679 0"/>
                    <body name="finger_mittel_mount1" pos="0 0 0.018">
                        <geom type="mesh" mesh="SDH_Mittelteil_Finger1" material="metal" group="1" euler="1.57079632679 1.57079632679 0" pos="0 0 -0.018"/>
                        <joint name="finger_mittel_1" pos="0 0 0" axis="0 1 0" limited="true" range="-2.9670597283903604 2.9670597283903604" damping="0.1" stiffness="1.0"/>
                        <body name="finger_kuppe_mount1" pos="0 0 0.086">
                            <joint name="finger_kuppe_1" pos="0 0 0" axis="0 1 0" limited="true" range="-2.9670597283903604 2.9670597283903604" damping="0.1" stiffness="1.0"/>
                            <geom type="mesh" mesh="SDH_Kuppe_Finger1" material="metal" group="1" euler="1.57079632679 1.57079632679 0" pos="0 0 -0.106"/>
                        </body>
                    </body>
                </body>

                <body name="finger_mount2" pos="0.018 0.031 0.025" axisangle="0 0 1 0.785398163397">
                    <joint name="finger_base_2" pos="0 0 0" axis="0 0 1" limited="true" range="-2.9670597283903604 2.9670597283903604" damping="0.1" stiffness="1.0"/>
                    <geom type="mesh" mesh="SDH_Gelenk_Finger1" material="metal" group="1" euler="1.57079632679 1.57079632679 0"/>
                    <body name="finger_mittel_mount2" pos="0 0 0.018">
                        <geom type="mesh" mesh="SDH_Mittelteil_Finger1" material="metal" group="1" euler="1.57079632679 1.57079632679 0" pos="0 0 -0.018"/>
                        <joint name="finger_mittel_2" pos="0 0 0" axis="0 1 0" limited="true" range="-2.9670597283903604 2.9670597283903604" damping="0.1" stiffness="1.0"/>
                        <body name="finger_kuppe_mount2" pos="0 0 0.086">
                            <joint name="finger_kuppe_2" pos="0 0 0" axis="0 1 0" limited="true" range="-2.9670597283903604 2.9670597283903604" damping="0.1" stiffness="1.0"/>
                            <geom type="mesh" mesh="SDH_Kuppe_Finger1" material="metal" group="1" euler="1.57079632679 1.57079632679 0" pos="0 0 -0.106"/>
                        </body>
                    </body>
                </body>

                <body name="finger_mount3" pos="0.018 -0.031 0.025" axisangle="0 0 1 -0.785398163397">
                    <joint name="finger_base_3" pos="0 0 0" axis="0 0 1" limited="true" range="-2.9670597283903604 2.9670597283903604" damping="0.1" stiffness="1.0"/>
                    <geom type="mesh" mesh="SDH_Gelenk_Finger1" material="metal" group="1" euler="1.57079632679 1.57079632679 0"/>
                    <body name="finger_mittel_mount3" pos="0 0 0.018">
                        <geom type="mesh" mesh="SDH_Mittelteil_Finger1" material="metal" group="1" euler="1.57079632679 1.57079632679 0" pos="0 0 -0.018"/>
                        <joint name="finger_mittel_3" pos="0 0 0" axis="0 1 0" limited="true" range="-2.9670597283903604 2.9670597283903604" damping="0.1" stiffness="1.0"/>
                        <body name="finger_kuppe_mount3" pos="0 0 0.086">
                            <joint name="finger_kuppe_3" pos="0 0 0" axis="0 1 0" limited="true" range="-2.9670597283903604 2.9670597283903604" damping="0.1" stiffness="1.0"/>
                            <geom type="mesh" mesh="SDH_Kuppe_Finger1" material="metal" group="1" euler="1.57079632679 1.57079632679 0" pos="0 0 -0.106"/>
                        </body>
                    </body>
                </body>

            </body>
        </body>
    </worldbody>
</mujoco>
